BuildError
werkzeug.routing.exceptions.BuildError: Could not build url for endpoint 'index'. Did you mean 'routes.index' instead?

Traceback (most recent call last)
File "/home/runner/S1Cloud/google_auth.py", line 210, in callback
return redirect(url_for("index"))
                ^^^^^^^^^^^^^^^^
File "/home/runner/S1Cloud/.pythonlibs/lib/python3.11/site-packages/flask/helpers.py", line 220, in url_for
return current_app.url_for(
       
File "/home/runner/S1Cloud/.pythonlibs/lib/python3.11/site-packages/flask/app.py", line 1084, in url_for
return self.handle_url_build_error(error, endpoint, values)
       ^^^^^^^^^^^^^^^^^^^^^^^^^^^^^^^^^^^^^^^^^^^^^^^^^^^^
File "/home/runner/S1Cloud/.pythonlibs/lib/python3.11/site-packages/flask/app.py", line 1073, in url_for
rv = url_adapter.build(  # type: ignore[union-attr]
     
File "/home/runner/S1Cloud/.pythonlibs/lib/python3.11/site-packages/werkzeug/routing/map.py", line 924, in build
raise BuildError(endpoint, values, method, self)
^^^^^^^^^^^^^^^^^^^^^^^^^^^^^^^^^^^^^^^^^^^^^^^^
During handling of the above exception, another exception occurred:
File "/home/runner/S1Cloud/.pythonlibs/lib/python3.11/site-packages/flask/app.py", line 1498, in __call__
return self.wsgi_app(environ, start_response)
       ^^^^^^^^^^^^^^^^^^^^^^^^^^^^^^^^^^^^^^
File "/home/runner/S1Cloud/.pythonlibs/lib/python3.11/site-packages/flask/app.py", line 1476, in wsgi_app
response = self.handle_exception(e)
           ^^^^^^^^^^^^^^^^^^^^^^^^
File "/home/runner/S1Cloud/.pythonlibs/lib/python3.11/site-packages/flask/app.py", line 1473, in wsgi_app
response = self.full_dispatch_request()
           ^^^^^^^^^^^^^^^^^^^^^^^^^^^^
File "/home/runner/S1Cloud/.pythonlibs/lib/python3.11/site-packages/flask/app.py", line 882, in full_dispatch_request
rv = self.handle_user_exception(e)
     ^^^^^^^^^^^^^^^^^^^^^^^^^^^^^
File "/home/runner/S1Cloud/.pythonlibs/lib/python3.11/site-packages/flask/app.py", line 880, in full_dispatch_request
rv = self.dispatch_request()
     ^^^^^^^^^^^^^^^^^^^^^^^
File "/home/runner/S1Cloud/.pythonlibs/lib/python3.11/site-packages/flask/app.py", line 865, in dispatch_request
return self.ensure_sync(self.view_functions[rule.endpoint])(**view_args)  # type: ignore[no-any-return]
       ^^^^^^^^^^^^^^^^^^^^^^^^^^^^^^^^^^^^^^^^^^^^^^^^^^^^^^^^^^^^^^^^^
File "/home/runner/S1Cloud/google_auth.py", line 240, in callback
return redirect(url_for("index"))
                ^^^^^^^^^^^^^^^^
File "/home/runner/S1Cloud/.pythonlibs/lib/python3.11/site-packages/flask/helpers.py", line 220, in url_for
return current_app.url_for(
       
File "/home/runner/S1Cloud/.pythonlibs/lib/python3.11/site-packages/flask/app.py", line 1084, in url_for
return self.handle_url_build_error(error, endpoint, values)
       ^^^^^^^^^^^^^^^^^^^^^^^^^^^^^^^^^^^^^^^^^^^^^^^^^^^^
File "/home/runner/S1Cloud/.pythonlibs/lib/python3.11/site-packages/flask/app.py", line 1073, in url_for
rv = url_adapter.build(  # type: ignore[union-attr]
     
File "/home/runner/S1Cloud/.pythonlibs/lib/python3.11/site-packages/werkzeug/routing/map.py", line 924, in build
raise BuildError(endpoint, values, method, self)
^^^^^^^^^^^^^^^^^^^^^^^^^^^^^^^^^^^^^^^^^^^^^^^^
werkzeug.routing.exceptions.BuildError: Could not build url for endpoint 'index'. Did you mean 'routes.index' instead?
The debugger caught an exception in your WSGI application. You can now look at the traceback which led to the error.
To switch between the interactive traceback and the plaintext one, you can click on the "Traceback" headline. From the text traceback you can also create a paste of it.

Brought to you by DON'T PANIC, your friendly Werkzeug powered traceback interpreter.