Traceback:
File "/home/runner/S1Cloud/.pythonlibs/lib/python3.11/site-packages/streamlit/runtime/scriptrunner/exec_code.py", line 88, in exec_func_with_error_handling
    result = func()
             ^^^^^^
File "/home/runner/S1Cloud/.pythonlibs/lib/python3.11/site-packages/streamlit/runtime/scriptrunner/script_runner.py", line 579, in code_to_exec
    exec(code, module.__dict__)
File "/home/runner/S1Cloud/main.py", line 205, in <module>
    clear_and_init_db()
File "/home/runner/S1Cloud/init_db.py", line 108, in clear_and_init_db
    init_questions()
File "/home/runner/S1Cloud/init_db.py", line 40, in init_questions
    db.session.commit()
File "/home/runner/S1Cloud/.pythonlibs/lib/python3.11/site-packages/sqlalchemy/orm/scoping.py", line 597, in commit
    return self._proxied.commit()
           ^^^^^^^^^^^^^^^^^^^^^^
File "/home/runner/S1Cloud/.pythonlibs/lib/python3.11/site-packages/sqlalchemy/orm/session.py", line 2028, in commit
    trans.commit(_to_root=True)
File "<string>", line 2, in commit
File "/home/runner/S1Cloud/.pythonlibs/lib/python3.11/site-packages/sqlalchemy/orm/state_changes.py", line 139, in _go
    ret_value = fn(self, *arg, **kw)
                ^^^^^^^^^^^^^^^^^^^^
File "/home/runner/S1Cloud/.pythonlibs/lib/python3.11/site-packages/sqlalchemy/orm/session.py", line 1313, in commit
    self._prepare_impl()
File "<string>", line 2, in _prepare_impl
File "/home/runner/S1Cloud/.pythonlibs/lib/python3.11/site-packages/sqlalchemy/orm/state_changes.py", line 139, in _go
    ret_value = fn(self, *arg, **kw)
                ^^^^^^^^^^^^^^^^^^^^
File "/home/runner/S1Cloud/.pythonlibs/lib/python3.11/site-packages/sqlalchemy/orm/session.py", line 1288, in _prepare_impl
    self.session.flush()
File "/home/runner/S1Cloud/.pythonlibs/lib/python3.11/site-packages/sqlalchemy/orm/session.py", line 4352, in flush
    self._flush(objects)
File "/home/runner/S1Cloud/.pythonlibs/lib/python3.11/site-packages/sqlalchemy/orm/session.py", line 4487, in _flush
    with util.safe_reraise():
File "/home/runner/S1Cloud/.pythonlibs/lib/python3.11/site-packages/sqlalchemy/util/langhelpers.py", line 146, in __exit__
    raise exc_value.with_traceback(exc_tb)
File "/home/runner/S1Cloud/.pythonlibs/lib/python3.11/site-packages/sqlalchemy/orm/session.py", line 4448, in _flush
    flush_context.execute()
File "/home/runner/S1Cloud/.pythonlibs/lib/python3.11/site-packages/sqlalchemy/orm/unitofwork.py", line 466, in execute
    rec.execute(self)
File "/home/runner/S1Cloud/.pythonlibs/lib/python3.11/site-packages/sqlalchemy/orm/unitofwork.py", line 642, in execute
    util.preloaded.orm_persistence.save_obj(
File "/home/runner/S1Cloud/.pythonlibs/lib/python3.11/site-packages/sqlalchemy/orm/persistence.py", line 93, in save_obj
    _emit_insert_statements(
File "/home/runner/S1Cloud/.pythonlibs/lib/python3.11/site-packages/sqlalchemy/orm/persistence.py", line 1143, in _emit_insert_statements
    result = connection.execute(
             ^^^^^^^^^^^^^^^^^^^
File "/home/runner/S1Cloud/.pythonlibs/lib/python3.11/site-packages/sqlalchemy/engine/base.py", line 1418, in execute
    return meth(
           ^^^^^
File "/home/runner/S1Cloud/.pythonlibs/lib/python3.11/site-packages/sqlalchemy/sql/elements.py", line 515, in _execute_on_connection
    return connection._execute_clauseelement(
           ^^^^^^^^^^^^^^^^^^^^^^^^^^^^^^^^^^
File "/home/runner/S1Cloud/.pythonlibs/lib/python3.11/site-packages/sqlalchemy/engine/base.py", line 1640, in _execute_clauseelement
    ret = self._execute_context(
          ^^^^^^^^^^^^^^^^^^^^^^
File "/home/runner/S1Cloud/.pythonlibs/lib/python3.11/site-packages/sqlalchemy/engine/base.py", line 1844, in _execute_context
    return self._exec_insertmany_context(dialect, context)
           ^^^^^^^^^^^^^^^^^^^^^^^^^^^^^^^^^^^^^^^^^^^^^^^
File "/home/runner/S1Cloud/.pythonlibs/lib/python3.11/site-packages/sqlalchemy/engine/base.py", line 2126, in _exec_insertmany_context
    self._handle_dbapi_exception(
File "/home/runner/S1Cloud/.pythonlibs/lib/python3.11/site-packages/sqlalchemy/engine/base.py", line 2355, in _handle_dbapi_exception
    raise sqlalchemy_exception.with_traceback(exc_info[2]) from e
File "/home/runner/S1Cloud/.pythonlibs/lib/python3.11/site-packages/sqlalchemy/engine/base.py", line 2118, in _exec_insertmany_context
    dialect.do_execute(
File "/home/runner/S1Cloud/.pythonlibs/lib/python3.11/site-packages/sqlalchemy/engine/default.py", line 941, in do_execute
    cursor.execute(statement, parameters)