INFO:googleapiclient.discovery_cache:file_cache is only supported with oauth2client<4.0.0
WARNING:google.auth.compute_engine._metadata:Compute Engine Metadata server unavailable on attempt 1 of 3. Reason: Remote end closed connection without response
WARNING:google.auth.compute_engine._metadata:Compute Engine Metadata server unavailable on attempt 2 of 3. Reason: Remote end closed connection without response
WARNING:google.auth.compute_engine._metadata:Compute Engine Metadata server unavailable on attempt 3 of 3. Reason: Remote end closed connection without response
WARNING:google.auth.compute_engine._metadata:Compute Engine Metadata server unavailable on attempt 1 of 5. Reason: [Errno -2] Name or service not known
WARNING:google.auth.compute_engine._metadata:Compute Engine Metadata server unavailable on attempt 2 of 5. Reason: [Errno -2] Name or service not known
WARNING:google.auth.compute_engine._metadata:Compute Engine Metadata server unavailable on attempt 3 of 5. Reason: [Errno -2] Name or service not known
WARNING:google.auth.compute_engine._metadata:Compute Engine Metadata server unavailable on attempt 4 of 5. Reason: [Errno -2] Name or service not known
WARNING:google.auth.compute_engine._metadata:Compute Engine Metadata server unavailable on attempt 5 of 5. Reason: [Errno -2] Name or service not known
WARNING:google.auth._default:No project ID could be determined. Consider running `gcloud config set project` or setting the GOOGLE_CLOUD_PROJECT environment variable
INFO:googleapiclient.discovery_cache:file_cache is only supported with oauth2client<4.0.0
WARNING:google.auth.compute_engine._metadata:Compute Engine Metadata server unavailable on attempt 1 of 3. Reason: Remote end closed connection without response
WARNING:google.auth.compute_engine._metadata:Compute Engine Metadata server unavailable on attempt 2 of 3. Reason: Remote end closed connection without response
WARNING:google.auth.compute_engine._metadata:Compute Engine Metadata server unavailable on attempt 3 of 3. Reason: Remote end closed connection without response
WARNING:google.auth.compute_engine._metadata:Compute Engine Metadata server unavailable on attempt 1 of 5. Reason: [Errno -2] Name or service not known
WARNING:google.auth.compute_engine._metadata:Compute Engine Metadata server unavailable on attempt 2 of 5. Reason: [Errno -2] Name or service not known
WARNING:google.auth.compute_engine._metadata:Compute Engine Metadata server unavailable on attempt 3 of 5. Reason: [Errno -2] Name or service not known
WARNING:google.auth.compute_engine._metadata:Compute Engine Metadata server unavailable on attempt 4 of 5. Reason: [Errno -2] Name or service not known
WARNING:google.auth.compute_engine._metadata:Compute Engine Metadata server unavailable on attempt 5 of 5. Reason: [Errno -2] Name or service not known
WARNING:google.auth._default:No project ID could be determined. Consider running `gcloud config set project` or setting the GOOGLE_CLOUD_PROJECT environment variable
WARNING:google.auth.compute_engine._metadata:Compute Engine Metadata server unavailable on attempt 1 of 5. Reason: HTTPConnectionPool(host='metadata.google.internal', port=80): Max retries exceeded with url: /computeMetadata/v1/universe/universe_domain (Caused by NameResolutionError("<urllib3.connection.HTTPConnection object at 0x7ff9c6baf650>: Failed to resolve 'metadata.google.internal' ([Errno -2] Name or service not known)"))
WARNING:google.auth.compute_engine._metadata:Compute Engine Metadata server unavailable on attempt 2 of 5. Reason: HTTPConnectionPool(host='metadata.google.internal', port=80): Max retries exceeded with url: /computeMetadata/v1/universe/universe_domain (Caused by NameResolutionError("<urllib3.connection.HTTPConnection object at 0x7ff9c6bcced0>: Failed to resolve 'metadata.google.internal' ([Errno -2] Name or service not known)"))
WARNING:google.auth.compute_engine._metadata:Compute Engine Metadata server unavailable on attempt 3 of 5. Reason: HTTPConnectionPool(host='metadata.google.internal', port=80): Max retries exceeded with url: /computeMetadata/v1/universe/universe_domain (Caused by NameResolutionError("<urllib3.connection.HTTPConnection object at 0x7ff9c6bcdfd0>: Failed to resolve 'metadata.google.internal' ([Errno -2] Name or service not known)"))
WARNING:google.auth.compute_engine._metadata:Compute Engine Metadata server unavailable on attempt 4 of 5. Reason: HTTPConnectionPool(host='metadata.google.internal', port=80): Max retries exceeded with url: /computeMetadata/v1/universe/universe_domain (Caused by NameResolutionError("<urllib3.connection.HTTPConnection object at 0x7ff9c6bcf310>: Failed to resolve 'metadata.google.internal' ([Errno -2] Name or service not known)"))